package com.danielbontii.tpms.exceptions;

import graphql.GraphQLError;
import graphql.GraphqlErrorBuilder;
import graphql.schema.DataFetchingEnvironment;
import org.springframework.graphql.execution.DataFetcherExceptionResolverAdapter;
import org.springframework.graphql.execution.ErrorType;
import org.springframework.stereotype.Component;

@Component
public class CustomExceptionResolver extends DataFetcherExceptionResolverAdapter {
    @Override
    protected GraphQLError resolveToSingleError(Throwable ex, DataFetchingEnvironment env) {
        if (ex instanceof NotFoundException) {
            return GraphqlErrorBuilder.newError()
                    .errorType(ErrorType.NOT_FOUND)
                    .message(ex.getMessage())
                    .path(env.getExecutionStepInfo().getPath())
                    .location(env.getField().getSourceLocation())
                    .build();
        }

        if (ex instanceof AlreadyExistsException) {
            //TODO: See if I can get CONFLICT instead of BAD_REQUEST later
            return GraphqlErrorBuilder.newError()
                    .errorType(ErrorType.BAD_REQUEST)
                    .message(ex.getMessage())
                    .path(env.getExecutionStepInfo().getPath())
                    .location(env.getField().getSourceLocation())
                    .build();
        }

        if (ex instanceof Exception) {
            return GraphqlErrorBuilder.newError()
                    .errorType(ErrorType.INTERNAL_ERROR)
                    .message("Something went wrong. Please try again later")
                    .path(env.getExecutionStepInfo().getPath())
                    .location(env.getField().getSourceLocation())
                    .build();
        }

        return null;
    }

}
